Workbook

Sheet original_dataset
A1: ORIGINAL DATASET
A4: store_id | B4: month | C4: region | D4: store_type | E4: marketing_spend | F4: footfall | G4: avg_discount_pct | H4: staff_count | I4: inventory_availability_pct | J4: competitor_distance_km | K4: holiday_flag | L4: customer_rating | M4: monthly_sales | N4: monthly_profit
A5: STR-1001 | B5: 45658 | C5: East | D5: Residential | E5: 70389.11 | F5: 8302 | G5: 0.042 | H5: 17 | I5: 75 | J5: 5.28 | K5: 1 | L5: 3.1 | M5: 658832.62 | N5: 84349.93
A6: STR-1001 | B6: 45689 | C6: East | D6: Residential | E6: 43827.89 | F6: 8487 | G6: 0.168 | H6: 23 | I6: 84.4 | J6: 4.31 | K6: 0 | L6: 2.8 | M6: 634436 | N6: 106130.54
A7: STR-1001 | B7: 45717 | C7: East | D7: Residential | E7: 59921.75 | F7: 9113 | G7: 0.133 | H7: 20 | I7: 88 | J7: 12 | K7: 0 | L7: 3.2 | M7: 678722.06 | N7: 101883.86
A8: STR-1001 | B8: 45748 | C8: East | D8: Residential | E8: 56856.63 | F8: 9431 | G8: 0.142 | H8: 23 | I8: 86.9 | J8: 4.97 | K8: 0 | L8: 3.4 | M8: 658920.3 | N8: 97910.37
A9: STR-1002 | B9: 45658 | C9: East | D9: High Street | E9: 48412.64 | F9: 9545 | G9: 0.231 | H9: 21 | I9: 97.6 | J9: 6.94 | K9: 1 | L9: 4.2 | M9: 741341.44 | N9: 119208.17
A10: STR-1002 | B10: 45689 | C10: East | D10: High Street | E10: 64811.21 | F10: 9792 | G10: 0.112 | H10: 20 | I10: 84.2 | J10: 2.88 | K10: 0 | L10: 4.2 | M10: 761835.34 | N10: 149602.23
A11: STR-1002 | B11: 45717 | C11: East | D11: High Street | E11: 46213.45 | F11: 10616 | G11: 0.122 | H11: 22 | I11: 85.2 | J11: 0.2 | K11: 1 | L11: 4.1 | M11: 806615.54 | N11: 131364.62
A12: STR-1002 | B12: 45748 | C12: East | D12: High Street | E12: 68148.52 | F12: 8567 | G12: 0.127 | H12: 23 | I12: 95.6 | J12: 0.8 | K12: 0 | L12: 3.9 | M12: 850164.26 | N12: 149262.75
A13: STR-1003 | B13: 45658 | C13: North | D13: Airport | E13: 71838.86 | F13: 10979 | G13: 0.215 | H13: 26 | I13: 88.6 | J13: 7.7 | K13: 1 | L13: 3.8 | M13: 930581.7 | N13: 136207.98
A14: STR-1003 | B14: 45689 | C14: North | D14: Airport | E14: 68133.44 | F14: 9459 | G14: 0.22 | H14: 21 | I14: 85 | J14: 1.91 | K14: 0 | L14: 4.2 | M14: 779010.94 | N14: 106328.09
A15: STR-1003 | B15: 45717 | C15: North | D15: Airport | E15: 34285.21 | F15: 9172 | G15: 0.213 | H15: 22 | I15: 88.3 | J15: 10.46 | K15: 1 | L15: 3.8 | M15: 723060.76 | N15: 123131.24
A16: STR-1003 | B16: 45748 | C16: North | D16: Airport | E16: 67979.88 | F16: 11230 | G16: 0.002 | H16: 28 | I16: 85.3 | J16: 7.16 | K16: 0 | L16: 3.8 | M16: 910791.94 | N16: 158891.28
... A37: STR-1009 | B37: 45658 | C37: North | D37: Residential | E37: 54597.83 | F37: 9429 | G37: 0.188 | H37: 21 | I37: 83.3 | J37: 11.71 | K37: 0 | L37: 4.2 | M37: 641865.03 | N37: 81342.58
A38: STR-1009 | B38: 45689 | C38: North | D38: Residential | E38: 73771.91 | F38: 11695 | G38: 0.07 | H38: 25 | I38: 84.7 | J38: 0.62 | K38: 0 | M38: 799477.76 | N38: 164974.41
A39: STR-1009 | B39: 45717 | C39: North | D39: Residential | E39: 74413.88 | F39: 9449 | G39: 0.039 | H39: 23 | I39: 92.1 | J39: 2.12 | K39: 0 | L39: 3.5 | M39: 798952.17 | N39: 161499.04
A40: STR-1009 | B40: 45748 | C40: North | D40: Residential | E40: 52483.77 | F40: 10453 | G40: 0.247 | H40: 25 | I40: 99 | J40: 6.31 | K40: 0 | L40: 3.6 | M40: 800979.78 | N40: 149242.27
A41: STR-1010 | B41: 45658 | C41: North | D41: Mall | E41: 75269.87 | F41: 8838 | G41: 0.092 | H41: 21 | I41: 83.1 | J41: 9.56 | K41: 1 | L41: 4.2 | M41: 820593.93 | N41: 115860.06
A42: STR-1010 | B42: 45689 | C42: North | D42: Mall | E42: 61245.41 | F42: 8156 | G42: 0.156 | H42: 19 | I42: 92.9 | J42: 9.05 | K42: 0 | L42: 3.8 | M42: 718330.53 | N42: 93247.9
A43: STR-1010 | B43: 45717 | C43: North | D43: Mall | E43: 93381.26 | F43: 7562 | G43: 0.198 | H43: 19 | I43: 82.9 | J43: 5.05 | K43: 0 | L43: 4 | M43: 736633.4 | N43: 115654.66
A44: STR-1010 | B44: 45748 | C44: North | D44: Mall | E44: 65012.19 | F44: 9598 | G44: 0.085 | H44: 24 | I44: 98.3 | J44: 0.89 | K44: 0 | L44: 3.8 | M44: 828623.85 | N44: 167320.52
A45: STR-1011 | B45: 45658 | C45: East | D45: Mall | E45: 40462.94 | F45: 3660 | G45: 0.218 | H45: 11 | I45: 95.2 | J45: 5.57 | K45: 0 | L45: 4.4 | M45: 592195.85 | N45: 92291.56
A46: STR-1011 | B46: 45689 | C46: East | D46: Mall | E46: 46123.88 | F46: 3227 | G46: 0.143 | H46: 10 | I46: 75.4 | J46: 1.06 | K46: 0 | L46: 4.4 | M46: 532644.46 | N46: 60681.32
A47: STR-1011 | B47: 45717 | C47: East | D47: Mall | E47: 68077.54 | F47: 3360 | G47: 0.128 | H47: 14 | I47: 88.2 | J47: 1.24 | K47: 1 | L47: 4 | M47: 657429.18 | N47: 88919.74
A48: STR-1011 | B48: 45748 | C48: East | D48: Mall | E48: 64882.14 | F48: 3642 | G48: 0.019 | H48: 13 | I48: 87.8 | J48: 4.52 | K48: 0 | L48: 4.2 | M48: 605178 | N48: 106958.74
A49: STR-1012 | B49: 45658 | C49: West | D49: Residential | E49: 138855.51 | F49: 5145 | G49: 0.06 | H49: 17 | I49: 88.2 | J49: 9.58 | K49: 0 | L49: 3.2 | M49: 595467.6 | N49: 104276.46
A50: STR-1012 | B50: 45689 | C50: West | D50: Residential | E50: 63630.21 | F50: 4460 | G50: 0.235 | H50: 14 | I50: 98.6 | J50: 5.52 | K50: 0 | L50: 3.5 | M50: 599603.4 | N50: 112685.12
... A75: STR-1018 | B75: 45717 | C75: East | D75: High Street | E75: 60571.82 | F75: 3193 | G75: 0.197 | H75: 7 | I75: 99 | J75: 1.43 | K75: 0 | L75: 3.2 | M75: 605023.87 | N75: 98545.81
A76: STR-1018 | B76: 45748 | C76: East | D76: High Street | E76: 55081.16 | F76: 5485 | G76: 0.036 | H76: 12 | I76: 88 | K76: 0 | L76: 3.5 | M76: 674774.09 | N76: 141917.59
A77: STR-1019 | B77: 45658 | C77: East | D77: Residential | E77: 46201.46 | F77: 5918 | G77: 0.277 | H77: 13 | I77: 78.8 | J77: 4.91 | K77: 0 | L77: 4.5 | M77: 616069.41 | N77: 54453.99
A78: STR-1019 | B78: 45689 | C78: East | D78: Residential | E78: 53762.92 | F78: 6821 | G78: 0.066 | H78: 19 | I78: 94.6 | J78: 7.03 | K78: 0 | L78: 4.4 | M78: 630829.94 | N78: 117090.02
A79: STR-1019 | B79: 45717 | C79: East | D79: Residential | E79: 70144.78 | F79: 6806 | G79: 0.178 | H79: 20 | I79: 93.1 | J79: 0.28 | K79: 1 | L79: 4.3 | M79: 788087.68 | N79: 116803.42
A80: STR-1019 | B80: 45748 | C80: East | D80: Residential | E80: 58749.63 | F80: 8252 | G80: 0.203 | H80: 20 | I80: 85.2 | J80: 3.61 | K80: 0 | L80: 4.5 | M80: 680840.36 | N80: 68007.68
A81: STR-1020 | B81: 45658 | C81: South | D81: High Street | E81: 56973.18 | F81: 6662 | G81: 0.1 | H81: 15 | I81: 77.7 | J81: 7.52 | K81: 1 | L81: 3.2 | M81: 643657.47 | N81: 87022.45
A82: STR-1020 | B82: 45689 | C82: South | D82: High Street | E82: 54872.82 | F82: 5962 | G82: 0.064 | H82: 12 | I82: 85.4 | J82: 2.58 | K82: 0 | L82: 2.9 | M82: 691112.6 | N82: 109212.83
A83: STR-1020 | B83: 45717 | C83: South | D83: High Street | E83: 80562.81 | F83: 7470 | G83: 0.172 | H83: 16 | I83: 83.5 | J83: 2.29 | K83: 0 | L83: 3.3 | M83: 776922.17 | N83: 150701.93
A84: STR-1020 | B84: 45748 | C84: South | D84: High Street | E84: 77999.9 | F84: 5974 | G84: 0.252 | H84: 14 | I84: 81.3 | J84: 2.39 | K84: 0 | L84: 3.2 | M84: 636561.34 | N84: 93861.06
A85: STR-1021 | B85: 45658 | C85: West | D85: Mall | E85: 60881.01 | F85: 5410 | G85: 0.179 | H85: 15 | I85: 83.9 | J85: 5.24 | K85: 0 | L85: 4.6 | M85: 621369.58 | N85: 85493.64
A86: STR-1021 | B86: 45689 | C86: West | D86: Mall | E86: 60628.38 | F86: 4451 | G86: 0.095 | H86: 10 | I86: 89.6 | J86: 3.17 | K86: 0 | L86: 4.6 | M86: 682208.01 | N86: 110318.84
...

Sheet cleaned_data
A1: CLEANED
A4: store_id | B4: month | C4: region | D4: store_type | E4: marketing_spend | F4: footfall | G4: avg_discount_pct | H4: staff_count | I4: inventory_availability_pct | J4: competitor_distance_km | K4: holiday_flag | L4: customer_rating | M4: monthly_sales | N4: monthly_profit
A5: STR-1001 | B5: 2025-01-01 | C5: East | D5: Residential | E5: 70389.11 | F5: 8302 | G5: 0.042 | H5: 17 | I5: 75 | J5: 5.28 | K5: 1 | L5: 3.1 | M5: 658832.62 | N5: 84349.93
A6: STR-1001 | B6: 2025-02-01 | C6: East | D6: Residential | E6: 43827.89 | F6: 8487 | G6: 0.168 | H6: 23 | I6: 84.4 | J6: 4.31 | K6: 0 | L6: 2.8 | M6: 634436 | N6: 106130.54
A7: STR-1001 | B7: 2025-03-01 | C7: East | D7: Residential | E7: 59921.75 | F7: 9113 | G7: 0.133 | H7: 20 | I7: 88 | J7: 12 | K7: 0 | L7: 3.2 | M7: 678722.06 | N7: 101883.86
A8: STR-1001 | B8: 2025-04-01 | C8: East | D8: Residential | E8: 56856.63 | F8: 9431 | G8: 0.142 | H8: 23 | I8: 86.9 | J8: 4.97 | K8: 0 | L8: 3.4 | M8: 658920.3 | N8: 97910.37
A9: STR-1002 | B9: 2025-01-01 | C9: East | D9: High Street | E9: 48412.64 | F9: 9545 | G9: 0.231 | H9: 21 | I9: 97.6 | J9: 6.94 | K9: 1 | L9: 4.2 | M9: 741341.44 | N9: 119208.17
A10: STR-1002 | B10: 2025-02-01 | C10: East | D10: High Street | E10: 64811.21 | F10: 9792 | G10: 0.112 | H10: 20 | I10: 84.2 | J10: 2.88 | K10: 0 | L10: 4.2 | M10: 761835.34 | N10: 149602.23
A11: STR-1002 | B11: 2025-03-01 | C11: East | D11: High Street | E11: 46213.45 | F11: 10616 | G11: 0.122 | H11: 22 | I11: 85.2 | J11: 0.2 | K11: 1 | L11: 4.1 | M11: 806615.54 | N11: 131364.62
A12: STR-1002 | B12: 2025-04-01 | C12: East | D12: High Street | E12: 68148.52 | F12: 8567 | G12: 0.127 | H12: 23 | I12: 95.6 | J12: 0.8 | K12: 0 | L12: 3.9 | M12: 850164.26 | N12: 149262.75
A13: STR-1003 | B13: 2025-01-01 | C13: North | D13: Airport | E13: 71838.86 | F13: 10979 | G13: 0.215 | H13: 26 | I13: 88.6 | J13: 7.7 | K13: 1 | L13: 3.8 | M13: 930581.7 | N13: 136207.98
A14: STR-1003 | B14: 2025-02-01 | C14: North | D14: Airport | E14: 68133.44 | F14: 9459 | G14: 0.22 | H14: 21 | I14: 85 | J14: 1.91 | K14: 0 | L14: 4.2 | M14: 779010.94 | N14: 106328.09
A15: STR-1003 | B15: 2025-03-01 | C15: North | D15: Airport | E15: 34285.21 | F15: 9172 | G15: 0.213 | H15: 22 | I15: 88.3 | J15: 10.46 | K15: 1 | L15: 3.8 | M15: 723060.76 | N15: 123131.24
A16: STR-1003 | B16: 2025-04-01 | C16: North | D16: Airport | E16: 67979.88 | F16: 11230 | G16: 0.002 | H16: 28 | I16: 85.3 | J16: 7.16 | K16: 0 | L16: 3.8 | M16: 910791.94 | N16: 158891.28
... A324: STR-1080 | B324: 2025-04-01 | C324: East | D324: Residential | E324: 40553.11 | F324: 5317 | G324: 0.165 | H324: 17 | I324: 84.3 | J324: 11.82 | K324: 0 | L324: 4.1 | M324: 559660.84 | N324: 71443.61

Sheet dummy_variables
A1: DUMMY VARIABLE
A4: store_id | B4: region | C4: store_type | D4: is_Airport | E4: is_Mall | F4: is_Residential | G4: is_North | H4: is_South | I4: is_West | J4: monthly_sales
A5: STR-1001 | B5: East | C5: Residential | D5: 0 | E5: 0 | F5: 1 | G5: 0 | H5: 0 | I5: 0 | J5: 658832.62
A6: STR-1001 | B6: East | C6: Residential | D6: 0 | E6: 0 | F6: 1 | G6: 0 | H6: 0 | I6: 0 | J6: 634436
A7: STR-1001 | B7: East | C7: Residential | D7: 0 | E7: 0 | F7: 1 | G7: 0 | H7: 0 | I7: 0 | J7: 678722.06
A8: STR-1001 | B8: East | C8: Residential | D8: 0 | E8: 0 | F8: 1 | G8: 0 | H8: 0 | I8: 0 | J8: 658920.3
A9: STR-1002 | B9: East | C9: High Street | D9: 0 | E9: 0 | F9: 0 | G9: 0 | H9: 0 | I9: 0 | J9: 741341.44
A10: STR-1002 | B10: East | C10: High Street | D10: 0 | E10: 0 | F10: 0 | G10: 0 | H10: 0 | I10: 0 | J10: 761835.34
A11: STR-1002 | B11: East | C11: High Street | D11: 0 | E11: 0 | F11: 0 | G11: 0 | H11: 0 | I11: 0 | J11: 806615.54
A12: STR-1002 | B12: East | C12: High Street | D12: 0 | E12: 0 | F12: 0 | G12: 0 | H12: 0 | I12: 0 | J12: 850164.26
A13: STR-1003 | B13: North | C13: Airport | D13: 1 | E13: 0 | F13: 0 | G13: 1 | H13: 0 | I13: 0 | J13: 930581.7
A14: STR-1003 | B14: North | C14: Airport | D14: 1 | E14: 0 | F14: 0 | G14: 1 | H14: 0 | I14: 0 | J14: 779010.94
A15: STR-1003 | B15: North | C15: Airport | D15: 1 | E15: 0 | F15: 0 | G15: 1 | H15: 0 | I15: 0 | J15: 723060.76
A16: STR-1003 | B16: North | C16: Airport | D16: 1 | E16: 0 | F16: 0 | G16: 1 | H16: 0 | I16: 0 | J16: 910791.94
... A324: STR-1080 | B324: East | C324: Residential | D324: 0 | E324: 0 | F324: 1 | G324: 0 | H324: 0 | I324: 0 | J324: 559660.84

Sheet simple_regression
A1: SIMPLE LINEAR REGRESSION MODELS
A4: MODEL 1: monthly_sales ~ footfall
A5: Independent variable (X) | B5: footfall
A6: Slope (coefficient) | B6: =SLOPE(cleaned_data!$M$5:$M$324,cleaned_data!$F$5:$F$324) -> 35.678031
A7: Intercept | B7: =INTERCEPT(cleaned_data!$M$5:$M$324,cleaned_data!$F$5:$F$324) -> 446410.58
A8: R-squared | B8: =RSQ(cleaned_data!$M$5:$M$324,cleaned_data!$F$5:$F$324) -> 0.73628534
A9: Correlation (r) | B9: =CORREL(cleaned_data!$M$5:$M$324,cleaned_data!$F$5:$F$324) -> 0.85807071
A10: Std error of slope | B10: =INDEX(LINEST(cleaned_data!$M$5:$M$324,cleaned_data!$F$5:$F$324,TRUE(),TRUE()),2,1) -> 1.1973783
A11: t-stat | B11: =INDEX(LINEST(cleaned_data!$M$5:$M$324,cleaned_data!$F$5:$F$324,TRUE(),TRUE()),1,1)/INDEX(LINEST(cleaned_data!$M$5:$M$324,cleaned_data!$F$5:$F$324,TRUE(),TRUE()),2,1) -> 29.796791
A12: p-value | B12: =TDIST(ABS(INDEX(LINEST(cleaned_data!$M$5:$M$324,cleaned_data!$F$5:$F$324,TRUE(),TRUE()),1,1)/INDEX(LINEST(cleaned_data!$M$5:$M$324,cleaned_data!$F$5:$F$324,TRUE(),TRUE()),2,1)),COUNT(cleaned_data!$F$5:$F$324)-2,2) -> 4.7503615e-94
A13: n (observations) | B13: =COUNT(cleaned_data!$F$5:$F$324) -> 320
A15: MODEL 2: monthly_sales ~ marketing_spend
A16: Independent variable (X) | B16: marketing_spend
A17: Slope (coefficient) | B17: =SLOPE(cleaned_data!$M$5:$M$324,cleaned_data!$E$5:$E$324) -> 2.1295753
A18: Intercept | B18: =INTERCEPT(cleaned_data!$M$5:$M$324,cleaned_data!$E$5:$E$324) -> 560777.35
A19: R-squared | B19: =RSQ(cleaned_data!$M$5:$M$324,cleaned_data!$E$5:$E$324) -> 0.16724469
A20: Correlation (r) | B20: =CORREL(cleaned_data!$M$5:$M$324,cleaned_data!$E$5:$E$324) -> 0.40895561
A21: Std error of slope | B21: =INDEX(LINEST(cleaned_data!$M$5:$M$324,cleaned_data!$E$5:$E$324,TRUE(),TRUE()),2,1) -> 0.26647838
A22: t-stat | B22: =INDEX(LINEST(cleaned_data!$M$5:$M$324,cleaned_data!$E$5:$E$324,TRUE(),TRUE()),1,1)/INDEX(LINEST(cleaned_data!$M$5:$M$324,cleaned_data!$E$5:$E$324,TRUE(),TRUE()),2,1) -> 7.9915501
A23: p-value | B23: =TDIST(ABS(INDEX(LINEST(cleaned_data!$M$5:$M$324,cleaned_data!$E$5:$E$324,TRUE(),TRUE()),1,1)/INDEX(LINEST(cleaned_data!$M$5:$M$324,cleaned_data!$E$5:$E$324,TRUE(),TRUE()),2,1)),COUNT(cleaned_data!$E$5:$E$324)-2,2) -> 2.4800615e-14
A24: n (observations) | B24: =COUNT(cleaned_data!$E$5:$E$324) -> 320
A26: MODEL 3 (supplementary): monthly_sales ~ staff_count
A27: Independent variable (X) | B27: staff_count
A28: Slope (coefficient) | B28: =SLOPE(cleaned_data!$M$5:$M$324,cleaned_data!$H$5:$H$324) -> 16984.029
A29: Intercept | B29: =INTERCEPT(cleaned_data!$M$5:$M$324,cleaned_data!$H$5:$H$324) -> 400551.47
A30: R-squared | B30: =RSQ(cleaned_data!$M$5:$M$324,cleaned_data!$H$5:$H$324) -> 0.65229045
A31: Correlation (r) | B31: =CORREL(cleaned_data!$M$5:$M$324,cleaned_data!$H$5:$H$324) -> 0.807645
A32: Std error of slope | B32: =INDEX(LINEST(cleaned_data!$M$5:$M$324,cleaned_data!$H$5:$H$324,TRUE(),TRUE()),2,1) -> 695.36841
A33: t-stat | B33: =INDEX(LINEST(cleaned_data!$M$5:$M$324,cleaned_data!$H$5:$H$324,TRUE(),TRUE()),1,1)/INDEX(LINEST(cleaned_data!$M$5:$M$324,cleaned_data!$H$5:$H$324,TRUE(),TRUE()),2,1) -> 24.424504
A34: p-value | B34: =TDIST(ABS(INDEX(LINEST(cleaned_data!$M$5:$M$324,cleaned_data!$H$5:$H$324,TRUE(),TRUE()),1,1)/INDEX(LINEST(cleaned_data!$M$5:$M$324,cleaned_data!$H$5:$H$324,TRUE(),TRUE()),2,1)),COUNT(cleaned_data!$H$5:$H$324)-2,2) -> 6.2501018e-75
A35: n (observations) | B35: =COUNT(cleaned_data!$H$5:$H$324) -> 320
A37: MODEL 4 (supplementary, weak): monthly_sales ~ avg_discount_pct
A38: Independent variable (X) | B38: avg_discount_pct
A39: Slope (coefficient) | B39: =SLOPE(cleaned_data!$M$5:$M$324,cleaned_data!$G$5:$G$324) -> -138730.45
A40: Intercept | B40: =INTERCEPT(cleaned_data!$M$5:$M$324,cleaned_data!$G$5:$G$324) -> 697835.63
A41: R-squared | B41: =RSQ(cleaned_data!$M$5:$M$324,cleaned_data!$G$5:$G$324) -> 0.008290503
A42: Correlation (r) | B42: =CORREL(cleaned_data!$M$5:$M$324,cleaned_data!$G$5:$G$324) -> -0.091052199
A43: Std error of slope | B43: =INDEX(LINEST(cleaned_data!$M$5:$M$324,cleaned_data!$G$5:$G$324,TRUE(),TRUE()),2,1) -> 85086.38
A44: t-stat | B44: =INDEX(LINEST(cleaned_data!$M$5:$M$324,cleaned_data!$G$5:$G$324,TRUE(),TRUE()),1,1)/INDEX(LINEST(cleaned_data!$M$5:$M$324,cleaned_data!$G$5:$G$324,TRUE(),TRUE()),2,1) -> -1.6304661
A45: p-value | B45: =TDIST(ABS(INDEX(LINEST(cleaned_data!$M$5:$M$324,cleaned_data!$G$5:$G$324,TRUE(),TRUE()),1,1)/INDEX(LINEST(cleaned_data!$M$5:$M$324,cleaned_data!$G$5:$G$324,TRUE(),TRUE()),2,1)),COUNT(cleaned_data!$G$5:$G$324)-2,2) -> 0.10399305
...

Sheet multiple_regression
A1: MULTIPLE LINEAR REGRESSION MODEL
A2: Y = monthly_sales. Predictors: footfall, marketing_spend, inventory_availability_pct, staff_count, is_Airport, is_Mall, is_Residential, is_North, is_South, is_West (dummy reference categories: store_type=High Street, region=East)
A4: Consolidated predictor matrix (referenced from cleaned_data and dummy_variables)
A5: monthly_sales | B5: footfall | C5: marketing_spend | D5: inventory_availability_pct | E5: staff_count | F5: is_Airport | G5: is_Mall | H5: is_Residential | I5: is_North | J5: is_South | K5: is_West | N5: MULTIPLE REGRESSION OUTPUT (LINEST)
A6: =cleaned_data!$M$5 -> 658832.62 | B6: =cleaned_data!$F$5 -> 8302 | C6: =cleaned_data!$E$5 -> 70389.11 | D6: =cleaned_data!$I$5 -> 75 | E6: =cleaned_data!$H$5 -> 17 | F6: =dummy_variables!$D$5 -> 0 | G6: =dummy_variables!$E$5 -> 0 | H6: =dummy_variables!$F$5 -> 1 | I6: =dummy_variables!$G$5 -> 0 | J6: =dummy_variables!$H$5 -> 0 | K6: =dummy_variables!$I$5 -> 0 | N6: Coefficients (last->first: const last, is_West first var):
A7: =cleaned_data!$M$6 -> 634436 | B7: =cleaned_data!$F$6 -> 8487 | C7: =cleaned_data!$E$6 -> 43827.89 | D7: =cleaned_data!$I$6 -> 84.4 | E7: =cleaned_data!$H$6 -> 23 | F7: =dummy_variables!$D$6 -> 0 | G7: =dummy_variables!$E$6 -> 0 | H7: =dummy_variables!$F$6 -> 1 | I7: =dummy_variables!$G$6 -> 0 | J7: =dummy_variables!$H$6 -> 0 | K7: =dummy_variables!$I$6 -> 0 | N7: is_West | O7: is_South | P7: is_North | Q7: is_Residential | R7: is_Mall | S7: is_Airport | T7: staff_count | U7: inventory_pct | V7: marketing_spend | W7: footfall | X7: intercept
A8: =cleaned_data!$M$7 -> 678722.06 | B8: =cleaned_data!$F$7 -> 9113 | C8: =cleaned_data!$E$7 -> 59921.75 | D8: =cleaned_data!$I$7 -> 88 | E8: =cleaned_data!$H$7 -> 20 | F8: =dummy_variables!$D$7 -> 0 | G8: =dummy_variables!$E$7 -> 0 | H8: =dummy_variables!$F$7 -> 1 | I8: =dummy_variables!$G$7 -> 0 | J8: =dummy_variables!$H$7 -> 0 | K8: =dummy_variables!$I$7 -> 0 | N8: {=LINEST($A$6:$A$325,$B$6:$K$325,TRUE(),TRUE())} -> 18892.972 | O8: 20900.936 | P8: 7601.2301 | Q8: -17402.348 | R8: 12191.542 | S8: 22531.679 | T8: 2790.4915 | U8: 3003.3311 | V8: 1.1736201 | W8: 28.829085 | X8: 103838.09
A9: =cleaned_data!$M$8 -> 658920.3 | B9: =cleaned_data!$F$8 -> 9431 | C9: =cleaned_data!$E$8 -> 56856.63 | D9: =cleaned_data!$I$8 -> 86.9 | E9: =cleaned_data!$H$8 -> 23 | F9: =dummy_variables!$D$8 -> 0 | G9: =dummy_variables!$E$8 -> 0 | H9: =dummy_variables!$F$8 -> 1 | I9: =dummy_variables!$G$8 -> 0 | J9: =dummy_variables!$H$8 -> 0 | K9: =dummy_variables!$I$8 -> 0 | N9: 6280.3984 | O9: 7094.5214 | P9: 7032.3394 | Q9: 6006.099 | R9: 6510.4519 | S9: 9298.282 | T9: 1254.6297 | U9: 458.63717 | V9: 0.12620488 | W9: 2.4804346 | X9: 42406.375
A10: =cleaned_data!$M$9 -> 741341.44 | B10: =cleaned_data!$F$9 -> 9545 | C10: =cleaned_data!$E$9 -> 48412.64 | D10: =cleaned_data!$I$9 -> 97.6 | E10: =cleaned_data!$H$9 -> 21 | F10: =dummy_variables!$D$9 -> 0 | G10: =dummy_variables!$E$9 -> 0 | H10: =dummy_variables!$F$9 -> 0 | I10: =dummy_variables!$G$9 -> 0 | J10: =dummy_variables!$H$9 -> 0 | K10: =dummy_variables!$I$9 -> 0 | N10: 0.82955523 | O10: 43529.796 | P10: #N/A | Q10: #N/A | R10: #N/A | S10: #N/A | T10: #N/A | U10: #N/A | V10: #N/A | W10: #N/A | X10: #N/A
A11: =cleaned_data!$M$10 -> 761835.34 | B11: =cleaned_data!$F$10 -> 9792 | C11: =cleaned_data!$E$10 -> 64811.21 | D11: =cleaned_data!$I$10 -> 84.2 | E11: =cleaned_data!$H$10 -> 20 | F11: =dummy_variables!$D$10 -> 0 | G11: =dummy_variables!$E$10 -> 0 | H11: =dummy_variables!$F$10 -> 0 | I11: =dummy_variables!$G$10 -> 0 | J11: =dummy_variables!$H$10 -> 0 | K11: =dummy_variables!$I$10 -> 0 | N11: 150.3904 | O11: 309 | P11: #N/A | Q11: #N/A | R11: #N/A | S11: #N/A | T11: #N/A | U11: #N/A | V11: #N/A | W11: #N/A | X11: #N/A
A12: =cleaned_data!$M$11 -> 806615.54 | B12: =cleaned_data!$F$11 -> 10616 | C12: =cleaned_data!$E$11 -> 46213.45 | D12: =cleaned_data!$I$11 -> 85.2 | E12: =cleaned_data!$H$11 -> 22 | F12: =dummy_variables!$D$11 -> 0 | G12: =dummy_variables!$E$11 -> 0 | H12: =dummy_variables!$F$11 -> 0 | I12: =dummy_variables!$G$11 -> 0 | J12: =dummy_variables!$H$11 -> 0 | K12: =dummy_variables!$I$11 -> 0 | N12: 2.8496621e+12 | O12: 5.8550653e+11 | P12: #N/A | Q12: #N/A | R12: #N/A | S12: #N/A | T12: #N/A | U12: #N/A | V12: #N/A | W12: #N/A | X12: #N/A
A13: =cleaned_data!$M$12 -> 850164.26 | B13: =cleaned_data!$F$12 -> 8567 | C13: =cleaned_data!$E$12 -> 68148.52 | D13: =cleaned_data!$I$12 -> 95.6 | E13: =cleaned_data!$H$12 -> 23 | F13: =dummy_variables!$D$12 -> 0 | G13: =dummy_variables!$E$12 -> 0 | H13: =dummy_variables!$F$12 -> 0 | I13: =dummy_variables!$G$12 -> 0 | J13: =dummy_variables!$H$12 -> 0 | K13: =dummy_variables!$I$12 -> 0 | N13: Note: cells with #N/A in rows 10-12 beyond column O are unused LINEST padding slots (normal behavior, not errors).
A14: =cleaned_data!$M$13 -> 930581.7 | B14: =cleaned_data!$F$13 -> 10979 | C14: =cleaned_data!$E$13 -> 71838.86 | D14: =cleaned_data!$I$13 -> 88.6 | E14: =cleaned_data!$H$13 -> 26 | F14: =dummy_variables!$D$13 -> 1 | G14: =dummy_variables!$E$13 -> 0 | H14: =dummy_variables!$F$13 -> 0 | I14: =dummy_variables!$G$13 -> 1 | J14: =dummy_variables!$H$13 -> 0 | K14: =dummy_variables!$I$13 -> 0 | N14: Row1=coefficients, Row2=std errors, Row3=R2 & SE(y), Row4=F-stat & df, Row5=SSreg & SSresid
A15: =cleaned_data!$M$14 -> 779010.94 | B15: =cleaned_data!$F$14 -> 9459 | C15: =cleaned_data!$E$14 -> 68133.44 | D15: =cleaned_data!$I$14 -> 85 | E15: =cleaned_data!$H$14 -> 21 | F15: =dummy_variables!$D$14 -> 1 | G15: =dummy_variables!$E$14 -> 0 | H15: =dummy_variables!$F$14 -> 0 | I15: =dummy_variables!$G$14 -> 1 | J15: =dummy_variables!$H$14 -> 0 | K15: =dummy_variables!$I$14 -> 0
A16: =cleaned_data!$M$15 -> 723060.76 | B16: =cleaned_data!$F$15 -> 9172 | C16: =cleaned_data!$E$15 -> 34285.21 | D16: =cleaned_data!$I$15 -> 88.3 | E16: =cleaned_data!$H$15 -> 22 | F16: =dummy_variables!$D$15 -> 1 | G16: =dummy_variables!$E$15 -> 0 | H16: =dummy_variables!$F$15 -> 0 | I16: =dummy_variables!$G$15 -> 1 | J16: =dummy_variables!$H$15 -> 0 | K16: =dummy_variables!$I$15 -> 0 | N16: Readable Coefficient Summary
A17: =cleaned_data!$M$16 -> 910791.94 | B17: =cleaned_data!$F$16 -> 11230 | C17: =cleaned_data!$E$16 -> 67979.88 | D17: =cleaned_data!$I$16 -> 85.3 | E17: =cleaned_data!$H$16 -> 28 | F17: =dummy_variables!$D$16 -> 1 | G17: =dummy_variables!$E$16 -> 0 | H17: =dummy_variables!$F$16 -> 0 | I17: =dummy_variables!$G$16 -> 1 | J17: =dummy_variables!$H$16 -> 0 | K17: =dummy_variables!$I$16 -> 0 | N17: Variable | O17: Coefficient | P17: Std Error | Q17: t-stat | R17: p-value
A18: =cleaned_data!$M$17 -> 922168.6 | B18: =cleaned_data!$F$17 -> 12775 | C18: =cleaned_data!$E$17 -> 71828.26 | D18: =cleaned_data!$I$17 -> 81.7 | E18: =cleaned_data!$H$17 -> 30 | F18: =dummy_variables!$D$17 -> 0 | G18: =dummy_variables!$E$17 -> 0 | H18: =dummy_variables!$F$17 -> 1 | I18: =dummy_variables!$G$17 -> 0 | J18: =dummy_variables!$H$17 -> 0 | K18: =dummy_variables!$I$17 -> 0 | N18: Intercept | O18: =X$8 -> 103838.09 | P18: =X$9 -> 42406.375 | Q18: =X$8/X$9 -> 2.4486434 | R18: =TDIST(ABS(X$8/X$9),309,2) -> 0.014895057
A19: =cleaned_data!$M$18 -> 726606.28 | B19: =cleaned_data!$F$18 -> 10054 | C19: =cleaned_data!$E$18 -> 55716.82 | D19: =cleaned_data!$I$18 -> 84.9 | E19: =cleaned_data!$H$18 -> 24 | F19: =dummy_variables!$D$18 -> 0 | G19: =dummy_variables!$E$18 -> 0 | H19: =dummy_variables!$F$18 -> 1 | I19: =dummy_variables!$G$18 -> 0 | J19: =dummy_variables!$H$18 -> 0 | K19: =dummy_variables!$I$18 -> 0 | N19: footfall | O19: =W$8 -> 28.829085 | P19: =W$9 -> 2.4804346 | Q19: =W$8/W$9 -> 11.622594 | R19: =TDIST(ABS(W$8/W$9),309,2) -> 3.7758838e-26
A20: =cleaned_data!$M$19 -> 746501.09 | B20: =cleaned_data!$F$19 -> 8895 | C20: =cleaned_data!$E$19 -> 59909.51 | D20: =cleaned_data!$I$19 -> 88.8 | E20: =cleaned_data!$H$19 -> 23 | F20: =dummy_variables!$D$19 -> 0 | G20: =dummy_variables!$E$19 -> 0 | H20: =dummy_variables!$F$19 -> 1 | I20: =dummy_variables!$G$19 -> 0 | J20: =dummy_variables!$H$19 -> 0 | K20: =dummy_variables!$I$19 -> 0 | N20: marketing_spend | O20: =V$8 -> 1.1736201 | P20: =V$9 -> 0.12620488 | Q20: =V$8/V$9 -> 9.299324 | R20: =TDIST(ABS(V$8/V$9),309,2) -> 2.6616222e-18
A21: =cleaned_data!$M$20 -> 834017.02 | B21: =cleaned_data!$F$20 -> 10940 | C21: =cleaned_data!$E$20 -> 75305.71 | D21: =cleaned_data!$I$20 -> 76.5 | E21: =cleaned_data!$H$20 -> 26 | F21: =dummy_variables!$D$20 -> 0 | G21: =dummy_variables!$E$20 -> 0 | H21: =dummy_variables!$F$20 -> 1 | I21: =dummy_variables!$G$20 -> 0 | J21: =dummy_variables!$H$20 -> 0 | K21: =dummy_variables!$I$20 -> 0 | N21: inventory_availability_pct | O21: =U$8 -> 3003.3311 | P21: =U$9 -> 458.63717 | Q21: =U$8/U$9 -> 6.5483812 | R21: =TDIST(ABS(U$8/U$9),309,2) -> 2.4238605e-10
A22: =cleaned_data!$M$21 -> 666152.52 | B22: =cleaned_data!$F$21 -> 7057 | C22: =cleaned_data!$E$21 -> 48804.22 | D22: =cleaned_data!$I$21 -> 87.7 | E22: =cleaned_data!$H$21 -> 15 | F22: =dummy_variables!$D$21 -> 0 | G22: =dummy_variables!$E$21 -> 0 | H22: =dummy_variables!$F$21 -> 1 | I22: =dummy_variables!$G$21 -> 0 | J22: =dummy_variables!$H$21 -> 1 | K22: =dummy_variables!$I$21 -> 0 | N22: staff_count | O22: =T$8 -> 2790.4915 | P22: =T$9 -> 1254.6297 | Q22: =T$8/T$9 -> 2.2241554 | R22: =TDIST(ABS(T$8/T$9),309,2) -> 0.026860383
A23: =cleaned_data!$M$22 -> 573155.19 | B23: =cleaned_data!$F$22 -> 4263 | C23: =cleaned_data!$E$22 -> 59117.9 | D23: =cleaned_data!$I$22 -> 87.6 | E23: =cleaned_data!$H$22 -> 9 | F23: =dummy_variables!$D$22 -> 0 | G23: =dummy_variables!$E$22 -> 0 | H23: =dummy_variables!$F$22 -> 1 | I23: =dummy_variables!$G$22 -> 0 | J23: =dummy_variables!$H$22 -> 1 | K23: =dummy_variables!$I$22 -> 0 | N23: is_Airport | O23: =S$8 -> 22531.679 | P23: =S$9 -> 9298.282 | Q23: =S$8/S$9 -> 2.4232088 | R23: =TDIST(ABS(S$8/S$9),309,2) -> 0.015958368
A24: =cleaned_data!$M$23 -> 666573.2 | B24: =cleaned_data!$F$23 -> 5538 | C24: =cleaned_data!$E$23 -> 78831.12 | D24: =cleaned_data!$I$23 -> 94.1 | E24: =cleaned_data!$H$23 -> 15 | F24: =dummy_variables!$D$23 -> 0 | G24: =dummy_variables!$E$23 -> 0 | H24: =dummy_variables!$F$23 -> 1 | I24: =dummy_variables!$G$23 -> 0 | J24: =dummy_variables!$H$23 -> 1 | K24: =dummy_variables!$I$23 -> 0 | N24: is_Mall | O24: =R$8 -> 12191.542 | P24: =R$9 -> 6510.4519 | Q24: =R$8/R$9 -> 1.8726106 | R24: =TDIST(ABS(R$8/R$9),309,2) -> 0.062066335
A25: =cleaned_data!$M$24 -> 591619.95 | B25: =cleaned_data!$F$24 -> 4865 | C25: =cleaned_data!$E$24 -> 41441.93 | D25: =cleaned_data!$I$24 -> 88.3 | E25: =cleaned_data!$H$24 -> 16 | F25: =dummy_variables!$D$24 -> 0 | G25: =dummy_variables!$E$24 -> 0 | H25: =dummy_variables!$F$24 -> 1 | I25: =dummy_variables!$G$24 -> 0 | J25: =dummy_variables!$H$24 -> 1 | K25: =dummy_variables!$I$24 -> 0 | N25: is_Residential | O25: =Q$8 -> -17402.348 | P25: =Q$9 -> 6006.099 | Q25: =Q$8/Q$9 -> -2.8974461 | R25: =TDIST(ABS(Q$8/Q$9),309,2) -> 0.0040309687
A26: =cleaned_data!$M$25 -> 415721.82 | B26: =cleaned_data!$F$25 -> 2822 | C26: =cleaned_data!$E$25 -> 30356.28 | D26: =cleaned_data!$I$25 -> 84.8 | E26: =cleaned_data!$H$25 -> 9 | F26: =dummy_variables!$D$25 -> 0 | G26: =dummy_variables!$E$25 -> 0 | H26: =dummy_variables!$F$25 -> 1 | I26: =dummy_variables!$G$25 -> 1 | J26: =dummy_variables!$H$25 -> 0 | K26: =dummy_variables!$I$25 -> 0 | N26: is_North | O26: =P$8 -> 7601.2301 | P26: =P$9 -> 7032.3394 | Q26: =P$8/P$9 -> 1.0808964 | R26: =TDIST(ABS(P$8/P$9),309,2) -> 0.28058609
A27: =cleaned_data!$M$26 -> 491905.13 | B27: =cleaned_data!$F$26 -> 2121 | C27: =cleaned_data!$E$26 -> 33518.88 | D27: =cleaned_data!$I$26 -> 88.5 | E27: =cleaned_data!$H$26 -> 8 | F27: =dummy_variables!$D$26 -> 0 | G27: =dummy_variables!$E$26 -> 0 | H27: =dummy_variables!$F$26 -> 1 | I27: =dummy_variables!$G$26 -> 1 | J27: =dummy_variables!$H$26 -> 0 | K27: =dummy_variables!$I$26 -> 0 | N27: is_South | O27: =O$8 -> 20900.936 | P27: =O$9 -> 7094.5214 | Q27: =O$8/O$9 -> 2.9460671 | R27: =TDIST(ABS(O$8/O$9),309,2) -> 0.0034631171
A28: =cleaned_data!$M$27 -> 555929.4 | B28: =cleaned_data!$F$27 -> 3364 | C28: =cleaned_data!$E$27 -> 42267.37 | D28: =cleaned_data!$I$27 -> 82 | E28: =cleaned_data!$H$27 -> 13 | F28: =dummy_variables!$D$27 -> 0 | G28: =dummy_variables!$E$27 -> 0 | H28: =dummy_variables!$F$27 -> 1 | I28: =dummy_variables!$G$27 -> 1 | J28: =dummy_variables!$H$27 -> 0 | K28: =dummy_variables!$I$27 -> 0 | N28: is_West | O28: =N$8 -> 18892.972 | P28: =N$9 -> 6280.3984 | Q28: =N$8/N$9 -> 3.0082443 | R28: =TDIST(ABS(N$8/N$9),309,2) -> 0.0028436531
A29: =cleaned_data!$M$28 -> 565810.99 | B29: =cleaned_data!$F$28 -> 2613 | C29: =cleaned_data!$E$28 -> 62060.43 | D29: =cleaned_data!$I$28 -> 92.1 | E29: =cleaned_data!$H$28 -> 12 | F29: =dummy_variables!$D$28 -> 0 | G29: =dummy_variables!$E$28 -> 0 | H29: =dummy_variables!$F$28 -> 1 | I29: =dummy_variables!$G$28 -> 1 | J29: =dummy_variables!$H$28 -> 0 | K29: =dummy_variables!$I$28 -> 0
A30: =cleaned_data!$M$29 -> 811771.14 | B30: =cleaned_data!$F$29 -> 10218 | C30: =cleaned_data!$E$29 -> 57696.69 | D30: =cleaned_data!$I$29 -> 94.8 | E30: =cleaned_data!$H$29 -> 25 | F30: =dummy_variables!$D$29 -> 0 | G30: =dummy_variables!$E$29 -> 1 | H30: =dummy_variables!$F$29 -> 0 | I30: =dummy_variables!$G$29 -> 0 | J30: =dummy_variables!$H$29 -> 0 | K30: =dummy_variables!$I$29 -> 1 | N30: R-squared | O30: =N10 -> 0.82955523
A31: =cleaned_data!$M$30 -> 800451.94 | B31: =cleaned_data!$F$30 -> 8927 | C31: =cleaned_data!$E$30 -> 172415.52 | D31: =cleaned_data!$I$30 -> 86.2 | E31: =cleaned_data!$H$30 -> 22 | F31: =dummy_variables!$D$30 -> 0 | G31: =dummy_variables!$E$30 -> 1 | H31: =dummy_variables!$F$30 -> 0 | I31: =dummy_variables!$G$30 -> 0 | J31: =dummy_variables!$H$30 -> 0 | K31: =dummy_variables!$I$30 -> 1 | N31: F-statistic | O31: =N11 -> 150.3904
A32: =cleaned_data!$M$31 -> 783672.82 | B32: =cleaned_data!$F$31 -> 9315 | C32: =cleaned_data!$E$31 -> 55270.52 | D32: =cleaned_data!$I$31 -> 91.9 | E32: =cleaned_data!$H$31 -> 23 | F32: =dummy_variables!$D$31 -> 0 | G32: =dummy_variables!$E$31 -> 1 | H32: =dummy_variables!$F$31 -> 0 | I32: =dummy_variables!$G$31 -> 0 | J32: =dummy_variables!$H$31 -> 0 | K32: =dummy_variables!$I$31 -> 1 | N32: n (observations) | O32: =320 -> 320
A33: =cleaned_data!$M$32 -> 701641.97 | B33: =cleaned_data!$F$32 -> 7223 | C33: =cleaned_data!$E$32 -> 52715.1 | D33: =cleaned_data!$I$32 -> 84.2 | E33: =cleaned_data!$H$32 -> 16 | F33: =dummy_variables!$D$32 -> 0 | G33: =dummy_variables!$E$32 -> 1 | H33: =dummy_variables!$F$32 -> 0 | I33: =dummy_variables!$G$32 -> 0 | J33: =dummy_variables!$H$32 -> 0 | K33: =dummy_variables!$I$32 -> 1 | N33: k (predictors) | O33: =10 -> 10
A34: =cleaned_data!$M$33 -> 511844.41 | B34: =cleaned_data!$F$33 -> 3988 | C34: =cleaned_data!$E$33 -> 68600.62 | D34: =cleaned_data!$I$33 -> 85 | E34: =cleaned_data!$H$33 -> 11 | F34: =dummy_variables!$D$33 -> 0 | G34: =dummy_variables!$E$33 -> 0 | H34: =dummy_variables!$F$33 -> 1 | I34: =dummy_variables!$G$33 -> 0 | J34: =dummy_variables!$H$33 -> 0 | K34: =dummy_variables!$I$33 -> 0
A35: =cleaned_data!$M$34 -> 537383.79 | B35: =cleaned_data!$F$34 -> 2390 | C35: =cleaned_data!$E$34 -> 63176.73 | D35: =cleaned_data!$I$34 -> 87.5 | E35: =cleaned_data!$H$34 -> 9 | F35: =dummy_variables!$D$34 -> 0 | G35: =dummy_variables!$E$34 -> 0 | H35: =dummy_variables!$F$34 -> 1 | I35: =dummy_variables!$G$34 -> 0 | J35: =dummy_variables!$H$34 -> 0 | K35: =dummy_variables!$I$34 -> 0
A36: =cleaned_data!$M$35 -> 500173.02 | B36: =cleaned_data!$F$35 -> 2471 | C36: =cleaned_data!$E$35 -> 44970.08 | D36: =cleaned_data!$I$35 -> 87.6 | E36: =cleaned_data!$H$35 -> 11 | F36: =dummy_variables!$D$35 -> 0 | G36: =dummy_variables!$E$35 -> 0 | H36: =dummy_variables!$F$35 -> 1 | I36: =dummy_variables!$G$35 -> 0 | J36: =dummy_variables!$H$35 -> 0 | K36: =dummy_variables!$I$35 -> 0
A37: =cleaned_data!$M$36 -> 427917.38 | B37: =cleaned_data!$F$36 -> 971 | C37: =cleaned_data!$E$36 -> 69816.35 | D37: =cleaned_data!$I$36 -> 89.9 | E37: =cleaned_data!$H$36 -> 5 | F37: =dummy_variables!$D$36 -> 0 | G37: =dummy_variables!$E$36 -> 0 | H37: =dummy_variables!$F$36 -> 1 | I37: =dummy_variables!$G$36 -> 0 | J37: =dummy_variables!$H$36 -> 0 | K37: =dummy_variables!$I$36 -> 0
A38: =cleaned_data!$M$37 -> 641865.03 | B38: =cleaned_data!$F$37 -> 9429 | C38: =cleaned_data!$E$37 -> 54597.83 | D38: =cleaned_data!$I$37 -> 83.3 | E38: =cleaned_data!$H$37 -> 21 | F38: =dummy_variables!$D$37 -> 0 | G38: =dummy_variables!$E$37 -> 0 | H38: =dummy_variables!$F$37 -> 1 | I38: =dummy_variables!$G$37 -> 1 | J38: =dummy_variables!$H$37 -> 0 | K38: =dummy_variables!$I$37 -> 0
A39: =cleaned_data!$M$38 -> 799477.76 | B39: =cleaned_data!$F$38 -> 11695 | C39: =cleaned_data!$E$38 -> 73771.91 | D39: =cleaned_data!$I$38 -> 84.7 | E39: =cleaned_data!$H$38 -> 25 | F39: =dummy_variables!$D$38 -> 0 | G39: =dummy_variables!$E$38 -> 0 | H39: =dummy_variables!$F$38 -> 1 | I39: =dummy_variables!$G$38 -> 1 | J39: =dummy_variables!$H$38 -> 0 | K39: =dummy_variables!$I$38 -> 0
A40: =cleaned_data!$M$39 -> 798952.17 | B40: =cleaned_data!$F$39 -> 9449 | C40: =cleaned_data!$E$39 -> 74413.88 | D40: =cleaned_data!$I$39 -> 92.1 | E40: =cleaned_data!$H$39 -> 23 | F40: =dummy_variables!$D$39 -> 0 | G40: =dummy_variables!$E$39 -> 0 | H40: =dummy_variables!$F$39 -> 1 | I40: =dummy_variables!$G$39 -> 1 | J40: =dummy_variables!$H$39 -> 0 | K40: =dummy_variables!$I$39 -> 0
A41: =cleaned_data!$M$40 -> 800979.78 | B41: =cleaned_data!$F$40 -> 10453 | C41: =cleaned_data!$E$40 -> 52483.77 | D41: =cleaned_data!$I$40 -> 99 | E41: =cleaned_data!$H$40 -> 25 | F41: =dummy_variables!$D$40 -> 0 | G41: =dummy_variables!$E$40 -> 0 | H41: =dummy_variables!$F$40 -> 1 | I41: =dummy_variables!$G$40 -> 1 | J41: =dummy_variables!$H$40 -> 0 | K41: =dummy_variables!$I$40 -> 0
...

Sheet prediction_residuals
A1: PREDICTED SALES & RESIDUAL CALCULATION (Final Model: Multiple Regression)
A2: predicted_sales = Intercept + sum(coefficient_i * X_i). residual = monthly_sales (actual) - predicted_sales. Coefficients pulled live from 'multiple_regression' sheet.
A4: store_id | B4: month | C4: region | D4: store_type | E4: monthly_sales (actual) | F4: predicted_sales | G4: residual
A5: =cleaned_data!$A$5 -> STR-1001 | B5: =cleaned_data!$B$5 -> 2025-01-01 | C5: =cleaned_data!$C$5 -> East | D5: =cleaned_data!$D$5 -> Residential | E5: =cleaned_data!$M$5 -> 658832.62 | F5: =multiple_regression!$O$18+multiple_regression!$O$19*cleaned_data!$F$5+multiple_regression!$O$20*cleaned_data!$E$5+multiple_regression!$O$21*cleaned_data!$I$5+multiple_regression!$O$22*cleaned_data!$H$5+multiple_regression!$O$23*dummy_variables!$D$5+multiple_regression!$O$24*dummy_variables!$E$5+multiple_regression!$O$25*dummy_variables!$F$5+multiple_regression!$O$26*dummy_variables!$G$5+multiple_regression!$O$27*dummy_variables!$H$5+multiple_regression!$O$28*dummy_variables!$I$5 -> 681073.06 | G5: =E5-F5 -> -22240.444
A6: =cleaned_data!$A$6 -> STR-1001 | B6: =cleaned_data!$B$6 -> 2025-02-01 | C6: =cleaned_data!$C$6 -> East | D6: =cleaned_data!$D$6 -> Residential | E6: =cleaned_data!$M$6 -> 634436 | F6: =multiple_regression!$O$18+multiple_regression!$O$19*cleaned_data!$F$6+multiple_regression!$O$20*cleaned_data!$E$6+multiple_regression!$O$21*cleaned_data!$I$6+multiple_regression!$O$22*cleaned_data!$H$6+multiple_regression!$O$23*dummy_variables!$D$6+multiple_regression!$O$24*dummy_variables!$E$6+multiple_regression!$O$25*dummy_variables!$F$6+multiple_regression!$O$26*dummy_variables!$G$6+multiple_regression!$O$27*dummy_variables!$H$6+multiple_regression!$O$28*dummy_variables!$I$6 -> 700207.92 | G6: =E6-F6 -> -65771.925
A7: =cleaned_data!$A$7 -> STR-1001 | B7: =cleaned_data!$B$7 -> 2025-03-01 | C7: =cleaned_data!$C$7 -> East | D7: =cleaned_data!$D$7 -> Residential | E7: =cleaned_data!$M$7 -> 678722.06 | F7: =multiple_regression!$O$18+multiple_regression!$O$19*cleaned_data!$F$7+multiple_regression!$O$20*cleaned_data!$E$7+multiple_regression!$O$21*cleaned_data!$I$7+multiple_regression!$O$22*cleaned_data!$H$7+multiple_regression!$O$23*dummy_variables!$D$7+multiple_regression!$O$24*dummy_variables!$E$7+multiple_regression!$O$25*dummy_variables!$F$7+multiple_regression!$O$26*dummy_variables!$G$7+multiple_regression!$O$27*dummy_variables!$H$7+multiple_regression!$O$28*dummy_variables!$I$7 -> 739583.53 | G7: =E7-F7 -> -60861.467
A8: =cleaned_data!$A$8 -> STR-1001 | B8: =cleaned_data!$B$8 -> 2025-04-01 | C8: =cleaned_data!$C$8 -> East | D8: =cleaned_data!$D$8 -> Residential | E8: =cleaned_data!$M$8 -> 658920.3 | F8: =multiple_regression!$O$18+multiple_regression!$O$19*cleaned_data!$F$8+multiple_regression!$O$20*cleaned_data!$E$8+multiple_regression!$O$21*cleaned_data!$I$8+multiple_regression!$O$22*cleaned_data!$H$8+multiple_regression!$O$23*dummy_variables!$D$8+multiple_regression!$O$24*dummy_variables!$E$8+multiple_regression!$O$25*dummy_variables!$F$8+multiple_regression!$O$26*dummy_variables!$G$8+multiple_regression!$O$27*dummy_variables!$H$8+multiple_regression!$O$28*dummy_variables!$I$8 -> 750221.7 | G8: =E8-F8 -> -91301.4
A9: =cleaned_data!$A$9 -> STR-1002 | B9: =cleaned_data!$B$9 -> 2025-01-01 | C9: =cleaned_data!$C$9 -> East | D9: =cleaned_data!$D$9 -> High Street | E9: =cleaned_data!$M$9 -> 741341.44 | F9: =multiple_regression!$O$18+multiple_regression!$O$19*cleaned_data!$F$9+multiple_regression!$O$20*cleaned_data!$E$9+multiple_regression!$O$21*cleaned_data!$I$9+multiple_regression!$O$22*cleaned_data!$H$9+multiple_regression!$O$23*dummy_variables!$D$9+multiple_regression!$O$24*dummy_variables!$E$9+multiple_regression!$O$25*dummy_variables!$F$9+multiple_regression!$O$26*dummy_variables!$G$9+multiple_regression!$O$27*dummy_variables!$H$9+multiple_regression!$O$28*dummy_variables!$I$9 -> 787555.19 | G9: =E9-F9 -> -46213.747
A10: =cleaned_data!$A$10 -> STR-1002 | B10: =cleaned_data!$B$10 -> 2025-02-01 | C10: =cleaned_data!$C$10 -> East | D10: =cleaned_data!$D$10 -> High Street | E10: =cleaned_data!$M$10 -> 761835.34 | F10: =multiple_regression!$O$18+multiple_regression!$O$19*cleaned_data!$F$10+multiple_regression!$O$20*cleaned_data!$E$10+multiple_regression!$O$21*cleaned_data!$I$10+multiple_regression!$O$22*cleaned_data!$H$10+multiple_regression!$O$23*dummy_variables!$D$10+multiple_regression!$O$24*dummy_variables!$E$10+multiple_regression!$O$25*dummy_variables!$F$10+multiple_regression!$O$26*dummy_variables!$G$10+multiple_regression!$O$27*dummy_variables!$H$10+multiple_regression!$O$28*dummy_variables!$I$10 -> 770886.53 | G10: =E10-F10 -> -9051.1938
A11: =cleaned_data!$A$11 -> STR-1002 | B11: =cleaned_data!$B$11 -> 2025-03-01 | C11: =cleaned_data!$C$11 -> East | D11: =cleaned_data!$D$11 -> High Street | E11: =cleaned_data!$M$11 -> 806615.54 | F11: =multiple_regression!$O$18+multiple_regression!$O$19*cleaned_data!$F$11+multiple_regression!$O$20*cleaned_data!$E$11+multiple_regression!$O$21*cleaned_data!$I$11+multiple_regression!$O$22*cleaned_data!$H$11+multiple_regression!$O$23*dummy_variables!$D$11+multiple_regression!$O$24*dummy_variables!$E$11+multiple_regression!$O$25*dummy_variables!$F$11+multiple_regression!$O$26*dummy_variables!$G$11+multiple_regression!$O$27*dummy_variables!$H$11+multiple_regression!$O$28*dummy_variables!$I$11 -> 781399.31 | G11: =E11-F11 -> 25216.23
A12: =cleaned_data!$A$12 -> STR-1002 | B12: =cleaned_data!$B$12 -> 2025-04-01 | C12: =cleaned_data!$C$12 -> East | D12: =cleaned_data!$D$12 -> High Street | E12: =cleaned_data!$M$12 -> 850164.26 | F12: =multiple_regression!$O$18+multiple_regression!$O$19*cleaned_data!$F$12+multiple_regression!$O$20*cleaned_data!$E$12+multiple_regression!$O$21*cleaned_data!$I$12+multiple_regression!$O$22*cleaned_data!$H$12+multiple_regression!$O$23*dummy_variables!$D$12+multiple_regression!$O$24*dummy_variables!$E$12+multiple_regression!$O$25*dummy_variables!$F$12+multiple_regression!$O$26*dummy_variables!$G$12+multiple_regression!$O$27*dummy_variables!$H$12+multiple_regression!$O$28*dummy_variables!$I$12 -> 782097.09 | G12: =E12-F12 -> 68067.173
A13: =cleaned_data!$A$13 -> STR-1003 | B13: =cleaned_data!$B$13 -> 2025-01-01 | C13: =cleaned_data!$C$13 -> North | D13: =cleaned_data!$D$13 -> Airport | E13: =cleaned_data!$M$13 -> 930581.7 | F13: =multiple_regression!$O$18+multiple_regression!$O$19*cleaned_data!$F$13+multiple_regression!$O$20*cleaned_data!$E$13+multiple_regression!$O$21*cleaned_data!$I$13+multiple_regression!$O$22*cleaned_data!$H$13+multiple_regression!$O$23*dummy_variables!$D$13+multiple_regression!$O$24*dummy_variables!$E$13+multiple_regression!$O$25*dummy_variables!$F$13+multiple_regression!$O$26*dummy_variables!$G$13+multiple_regression!$O$27*dummy_variables!$H$13+multiple_regression!$O$28*dummy_variables!$I$13 -> 873444.96 | G13: =E13-F13 -> 57136.737
A14: =cleaned_data!$A$14 -> STR-1003 | B14: =cleaned_data!$B$14 -> 2025-02-01 | C14: =cleaned_data!$C$14 -> North | D14: =cleaned_data!$D$14 -> Airport | E14: =cleaned_data!$M$14 -> 779010.94 | F14: =multiple_regression!$O$18+multiple_regression!$O$19*cleaned_data!$F$14+multiple_regression!$O$20*cleaned_data!$E$14+multiple_regression!$O$21*cleaned_data!$I$14+multiple_regression!$O$22*cleaned_data!$H$14+multiple_regression!$O$23*dummy_variables!$D$14+multiple_regression!$O$24*dummy_variables!$E$14+multiple_regression!$O$25*dummy_variables!$F$14+multiple_regression!$O$26*dummy_variables!$G$14+multiple_regression!$O$27*dummy_variables!$H$14+multiple_regression!$O$28*dummy_variables!$I$14 -> 800511.55 | G14: =E14-F14 -> -21500.61
A15: =cleaned_data!$A$15 -> STR-1003 | B15: =cleaned_data!$B$15 -> 2025-03-01 | C15: =cleaned_data!$C$15 -> North | D15: =cleaned_data!$D$15 -> Airport | E15: =cleaned_data!$M$15 -> 723060.76 | F15: =multiple_regression!$O$18+multiple_regression!$O$19*cleaned_data!$F$15+multiple_regression!$O$20*cleaned_data!$E$15+multiple_regression!$O$21*cleaned_data!$I$15+multiple_regression!$O$22*cleaned_data!$H$15+multiple_regression!$O$23*dummy_variables!$D$15+multiple_regression!$O$24*dummy_variables!$E$15+multiple_regression!$O$25*dummy_variables!$F$15+multiple_regression!$O$26*dummy_variables!$G$15+multiple_regression!$O$27*dummy_variables!$H$15+multiple_regression!$O$28*dummy_variables!$I$15 -> 765214.12 | G15: =E15-F15 -> -42153.364
A16: =cleaned_data!$A$16 -> STR-1003 | B16: =cleaned_data!$B$16 -> 2025-04-01 | C16: =cleaned_data!$C$16 -> North | D16: =cleaned_data!$D$16 -> Airport | E16: =cleaned_data!$M$16 -> 910791.94 | F16: =multiple_regression!$O$18+multiple_regression!$O$19*cleaned_data!$F$16+multiple_regression!$O$20*cleaned_data!$E$16+multiple_regression!$O$21*cleaned_data!$I$16+multiple_regression!$O$22*cleaned_data!$H$16+multiple_regression!$O$23*dummy_variables!$D$16+multiple_regression!$O$24*dummy_variables!$E$16+multiple_regression!$O$25*dummy_variables!$F$16+multiple_regression!$O$26*dummy_variables!$G$16+multiple_regression!$O$27*dummy_variables!$H$16+multiple_regression!$O$28*dummy_variables!$I$16 -> 871822.08 | G16: =E16-F16 -> 38969.862
A17: =cleaned_data!$A$17 -> STR-1004 | B17: =cleaned_data!$B$17 -> 2025-01-01 | C17: =cleaned_data!$C$17 -> East | D17: =cleaned_data!$D$17 -> Residential | E17: =cleaned_data!$M$17 -> 922168.6 | F17: =multiple_regression!$O$18+multiple_regression!$O$19*cleaned_data!$F$17+multiple_regression!$O$20*cleaned_data!$E$17+multiple_regression!$O$21*cleaned_data!$I$17+multiple_regression!$O$22*cleaned_data!$H$17+multiple_regression!$O$23*dummy_variables!$D$17+multiple_regression!$O$24*dummy_variables!$E$17+multiple_regression!$O$25*dummy_variables!$F$17+multiple_regression!$O$26*dummy_variables!$G$17+multiple_regression!$O$27*dummy_variables!$H$17+multiple_regression!$O$28*dummy_variables!$I$17 -> 868113.28 | G17: =E17-F17 -> 54055.315
A18: =cleaned_data!$A$18 -> STR-1004 | B18: =cleaned_data!$B$18 -> 2025-02-01 | C18: =cleaned_data!$C$18 -> East | D18: =cleaned_data!$D$18 -> Residential | E18: =cleaned_data!$M$18 -> 726606.28 | F18: =multiple_regression!$O$18+multiple_regression!$O$19*cleaned_data!$F$18+multiple_regression!$O$20*cleaned_data!$E$18+multiple_regression!$O$21*cleaned_data!$I$18+multiple_regression!$O$22*cleaned_data!$H$18+multiple_regression!$O$23*dummy_variables!$D$18+multiple_regression!$O$24*dummy_variables!$E$18+multiple_regression!$O$25*dummy_variables!$F$18+multiple_regression!$O$26*dummy_variables!$G$18+multiple_regression!$O$27*dummy_variables!$H$18+multiple_regression!$O$28*dummy_variables!$I$18 -> 763628.35 | G18: =E18-F18 -> -37022.065
A19: =cleaned_data!$A$19 -> STR-1004 | B19: =cleaned_data!$B$19 -> 2025-03-01 | C19: =cleaned_data!$C$19 -> East | D19: =cleaned_data!$D$19 -> Residential | E19: =cleaned_data!$M$19 -> 746501.09 | F19: =multiple_regression!$O$18+multiple_regression!$O$19*cleaned_data!$F$19+multiple_regression!$O$20*cleaned_data!$E$19+multiple_regression!$O$21*cleaned_data!$I$19+multiple_regression!$O$22*cleaned_data!$H$19+multiple_regression!$O$23*dummy_variables!$D$19+multiple_regression!$O$24*dummy_variables!$E$19+multiple_regression!$O$25*dummy_variables!$F$19+multiple_regression!$O$26*dummy_variables!$G$19+multiple_regression!$O$27*dummy_variables!$H$19+multiple_regression!$O$28*dummy_variables!$I$19 -> 744058.56 | G19: =E19-F19 -> 2442.5298
A20: =cleaned_data!$A$20 -> STR-1004 | B20: =cleaned_data!$B$20 -> 2025-04-01 | C20: =cleaned_data!$C$20 -> East | D20: =cleaned_data!$D$20 -> Residential | E20: =cleaned_data!$M$20 -> 834017.02 | F20: =multiple_regression!$O$18+multiple_regression!$O$19*cleaned_data!$F$20+multiple_regression!$O$20*cleaned_data!$E$20+multiple_regression!$O$21*cleaned_data!$I$20+multiple_regression!$O$22*cleaned_data!$H$20+multiple_regression!$O$23*dummy_variables!$D$20+multiple_regression!$O$24*dummy_variables!$E$20+multiple_regression!$O$25*dummy_variables!$F$20+multiple_regression!$O$26*dummy_variables!$G$20+multiple_regression!$O$27*dummy_variables!$H$20+multiple_regression!$O$28*dummy_variables!$I$20 -> 792513.83 | G20: =E20-F20 -> 41503.189
A21: =cleaned_data!$A$21 -> STR-1005 | B21: =cleaned_data!$B$21 -> 2025-01-01 | C21: =cleaned_data!$C$21 -> South | D21: =cleaned_data!$D$21 -> Residential | E21: =cleaned_data!$M$21 -> 666152.52 | F21: =multiple_regression!$O$18+multiple_regression!$O$19*cleaned_data!$F$21+multiple_regression!$O$20*cleaned_data!$E$21+multiple_regression!$O$21*cleaned_data!$I$21+multiple_regression!$O$22*cleaned_data!$H$21+multiple_regression!$O$23*dummy_variables!$D$21+multiple_regression!$O$24*dummy_variables!$E$21+multiple_regression!$O$25*dummy_variables!$F$21+multiple_regression!$O$26*dummy_variables!$G$21+multiple_regression!$O$27*dummy_variables!$H$21+multiple_regression!$O$28*dummy_variables!$I$21 -> 673310.65 | G21: =E21-F21 -> -7158.1303
A22: =cleaned_data!$A$22 -> STR-1005 | B22: =cleaned_data!$B$22 -> 2025-02-01 | C22: =cleaned_data!$C$22 -> South | D22: =cleaned_data!$D$22 -> Residential | E22: =cleaned_data!$M$22 -> 573155.19 | F22: =multiple_regression!$O$18+multiple_regression!$O$19*cleaned_data!$F$22+multiple_regression!$O$20*cleaned_data!$E$22+multiple_regression!$O$21*cleaned_data!$I$22+multiple_regression!$O$22*cleaned_data!$H$22+multiple_regression!$O$23*dummy_variables!$D$22+multiple_regression!$O$24*dummy_variables!$E$22+multiple_regression!$O$25*dummy_variables!$F$22+multiple_regression!$O$26*dummy_variables!$G$22+multiple_regression!$O$27*dummy_variables!$H$22+multiple_regression!$O$28*dummy_variables!$I$22 -> 587823.25 | G22: =E22-F22 -> -14668.056
A23: =cleaned_data!$A$23 -> STR-1005 | B23: =cleaned_data!$B$23 -> 2025-03-01 | C23: =cleaned_data!$C$23 -> South | D23: =cleaned_data!$D$23 -> Residential | E23: =cleaned_data!$M$23 -> 666573.2 | F23: =multiple_regression!$O$18+multiple_regression!$O$19*cleaned_data!$F$23+multiple_regression!$O$20*cleaned_data!$E$23+multiple_regression!$O$21*cleaned_data!$I$23+multiple_regression!$O$22*cleaned_data!$H$23+multiple_regression!$O$23*dummy_variables!$D$23+multiple_regression!$O$24*dummy_variables!$E$23+multiple_regression!$O$25*dummy_variables!$F$23+multiple_regression!$O$26*dummy_variables!$G$23+multiple_regression!$O$27*dummy_variables!$H$23+multiple_regression!$O$28*dummy_variables!$I$23 -> 683980.76 | G23: =E23-F23 -> -17407.561
A24: =cleaned_data!$A$24 -> STR-1005 | B24: =cleaned_data!$B$24 -> 2025-04-01 | C24: =cleaned_data!$C$24 -> South | D24: =cleaned_data!$D$24 -> Residential | E24: =cleaned_data!$M$24 -> 591619.95 | F24: =multiple_regression!$O$18+multiple_regression!$O$19*cleaned_data!$F$24+multiple_regression!$O$20*cleaned_data!$E$24+multiple_regression!$O$21*cleaned_data!$I$24+multiple_regression!$O$22*cleaned_data!$H$24+multiple_regression!$O$23*dummy_variables!$D$24+multiple_regression!$O$24*dummy_variables!$E$24+multiple_regression!$O$25*dummy_variables!$F$24+multiple_regression!$O$26*dummy_variables!$G$24+multiple_regression!$O$27*dummy_variables!$H$24+multiple_regression!$O$28*dummy_variables!$I$24 -> 606069.25 | G24: =E24-F24 -> -14449.304
A25: =cleaned_data!$A$25 -> STR-1006 | B25: =cleaned_data!$B$25 -> 2025-01-01 | C25: =cleaned_data!$C$25 -> North | D25: =cleaned_data!$D$25 -> Residential | E25: =cleaned_data!$M$25 -> 415721.82 | F25: =multiple_regression!$O$18+multiple_regression!$O$19*cleaned_data!$F$25+multiple_regression!$O$20*cleaned_data!$E$25+multiple_regression!$O$21*cleaned_data!$I$25+multiple_regression!$O$22*cleaned_data!$H$25+multiple_regression!$O$23*dummy_variables!$D$25+multiple_regression!$O$24*dummy_variables!$E$25+multiple_regression!$O$25*dummy_variables!$F$25+multiple_regression!$O$26*dummy_variables!$G$25+multiple_regression!$O$27*dummy_variables!$H$25+multiple_regression!$O$28*dummy_variables!$I$25 -> 490816.29 | G25: =E25-F25 -> -75094.467
A26: =cleaned_data!$A$26 -> STR-1006 | B26: =cleaned_data!$B$26 -> 2025-02-01 | C26: =cleaned_data!$C$26 -> North | D26: =cleaned_data!$D$26 -> Residential | E26: =cleaned_data!$M$26 -> 491905.13 | F26: =multiple_regression!$O$18+multiple_regression!$O$19*cleaned_data!$F$26+multiple_regression!$O$20*cleaned_data!$E$26+multiple_regression!$O$21*cleaned_data!$I$26+multiple_regression!$O$22*cleaned_data!$H$26+multiple_regression!$O$23*dummy_variables!$D$26+multiple_regression!$O$24*dummy_variables!$E$26+multiple_regression!$O$25*dummy_variables!$F$26+multiple_regression!$O$26*dummy_variables!$G$26+multiple_regression!$O$27*dummy_variables!$H$26+multiple_regression!$O$28*dummy_variables!$I$26 -> 482640.62 | G26: =E26-F26 -> 9264.5072
A27: =cleaned_data!$A$27 -> STR-1006 | B27: =cleaned_data!$B$27 -> 2025-03-01 | C27: =cleaned_data!$C$27 -> North | D27: =cleaned_data!$D$27 -> Residential | E27: =cleaned_data!$M$27 -> 555929.4 | F27: =multiple_regression!$O$18+multiple_regression!$O$19*cleaned_data!$F$27+multiple_regression!$O$20*cleaned_data!$E$27+multiple_regression!$O$21*cleaned_data!$I$27+multiple_regression!$O$22*cleaned_data!$H$27+multiple_regression!$O$23*dummy_variables!$D$27+multiple_regression!$O$24*dummy_variables!$E$27+multiple_regression!$O$25*dummy_variables!$F$27+multiple_regression!$O$26*dummy_variables!$G$27+multiple_regression!$O$27*dummy_variables!$H$27+multiple_regression!$O$28*dummy_variables!$I$27 -> 523173.38 | G27: =E27-F27 -> 32756.015
A28: =cleaned_data!$A$28 -> STR-1006 | B28: =cleaned_data!$B$28 -> 2025-04-01 | C28: =cleaned_data!$C$28 -> North | D28: =cleaned_data!$D$28 -> Residential | E28: =cleaned_data!$M$28 -> 565810.99 | F28: =multiple_regression!$O$18+multiple_regression!$O$19*cleaned_data!$F$28+multiple_regression!$O$20*cleaned_data!$E$28+multiple_regression!$O$21*cleaned_data!$I$28+multiple_regression!$O$22*cleaned_data!$H$28+multiple_regression!$O$23*dummy_variables!$D$28+multiple_regression!$O$24*dummy_variables!$E$28+multiple_regression!$O$25*dummy_variables!$F$28+multiple_regression!$O$26*dummy_variables!$G$28+multiple_regression!$O$27*dummy_variables!$H$28+multiple_regression!$O$28*dummy_variables!$I$28 -> 552295.43 | G28: =E28-F28 -> 13515.564
A29: =cleaned_data!$A$29 -> STR-1007 | B29: =cleaned_data!$B$29 -> 2025-01-01 | C29: =cleaned_data!$C$29 -> West | D29: =cleaned_data!$D$29 -> Mall | E29: =cleaned_data!$M$29 -> 811771.14 | F29: =multiple_regression!$O$18+multiple_regression!$O$19*cleaned_data!$F$29+multiple_regression!$O$20*cleaned_data!$E$29+multiple_regression!$O$21*cleaned_data!$I$29+multiple_regression!$O$22*cleaned_data!$H$29+multiple_regression!$O$23*dummy_variables!$D$29+multiple_regression!$O$24*dummy_variables!$E$29+multiple_regression!$O$25*dummy_variables!$F$29+multiple_regression!$O$26*dummy_variables!$G$29+multiple_regression!$O$27*dummy_variables!$H$29+multiple_regression!$O$28*dummy_variables!$I$29 -> 851690.26 | G29: =E29-F29 -> -39919.121
A30: =cleaned_data!$A$30 -> STR-1007 | B30: =cleaned_data!$B$30 -> 2025-02-01 | C30: =cleaned_data!$C$30 -> West | D30: =cleaned_data!$D$30 -> Mall | E30: =cleaned_data!$M$30 -> 800451.94 | F30: =multiple_regression!$O$18+multiple_regression!$O$19*cleaned_data!$F$30+multiple_regression!$O$20*cleaned_data!$E$30+multiple_regression!$O$21*cleaned_data!$I$30+multiple_regression!$O$22*cleaned_data!$H$30+multiple_regression!$O$23*dummy_variables!$D$30+multiple_regression!$O$24*dummy_variables!$E$30+multiple_regression!$O$25*dummy_variables!$F$30+multiple_regression!$O$26*dummy_variables!$G$30+multiple_regression!$O$27*dummy_variables!$H$30+multiple_regression!$O$28*dummy_variables!$I$30 -> 914908.11 | G30: =E30-F30 -> -114456.17
A31: =cleaned_data!$A$31 -> STR-1007 | B31: =cleaned_data!$B$31 -> 2025-03-01 | C31: =cleaned_data!$C$31 -> West | D31: =cleaned_data!$D$31 -> Mall | E31: =cleaned_data!$M$31 -> 783672.82 | F31: =multiple_regression!$O$18+multiple_regression!$O$19*cleaned_data!$F$31+multiple_regression!$O$20*cleaned_data!$E$31+multiple_regression!$O$21*cleaned_data!$I$31+multiple_regression!$O$22*cleaned_data!$H$31+multiple_regression!$O$23*dummy_variables!$D$31+multiple_regression!$O$24*dummy_variables!$E$31+multiple_regression!$O$25*dummy_variables!$F$31+multiple_regression!$O$26*dummy_variables!$G$31+multiple_regression!$O$27*dummy_variables!$H$31+multiple_regression!$O$28*dummy_variables!$I$31 -> 808519.55 | G31: =E31-F31 -> -24846.733
A32: =cleaned_data!$A$32 -> STR-1007 | B32: =cleaned_data!$B$32 -> 2025-04-01 | C32: =cleaned_data!$C$32 -> West | D32: =cleaned_data!$D$32 -> Mall | E32: =cleaned_data!$M$32 -> 701641.97 | F32: =multiple_regression!$O$18+multiple_regression!$O$19*cleaned_data!$F$32+multiple_regression!$O$20*cleaned_data!$E$32+multiple_regression!$O$21*cleaned_data!$I$32+multiple_regression!$O$22*cleaned_data!$H$32+multiple_regression!$O$23*dummy_variables!$D$32+multiple_regression!$O$24*dummy_variables!$E$32+multiple_regression!$O$25*dummy_variables!$F$32+multiple_regression!$O$26*dummy_variables!$G$32+multiple_regression!$O$27*dummy_variables!$H$32+multiple_regression!$O$28*dummy_variables!$I$32 -> 702550.92 | G32: =E32-F32 -> -908.95466
A33: =cleaned_data!$A$33 -> STR-1008 | B33: =cleaned_data!$B$33 -> 2025-01-01 | C33: =cleaned_data!$C$33 -> East | D33: =cleaned_data!$D$33 -> Residential | E33: =cleaned_data!$M$33 -> 511844.41 | F33: =multiple_regression!$O$18+multiple_regression!$O$19*cleaned_data!$F$33+multiple_regression!$O$20*cleaned_data!$E$33+multiple_regression!$O$21*cleaned_data!$I$33+multiple_regression!$O$22*cleaned_data!$H$33+multiple_regression!$O$23*dummy_variables!$D$33+multiple_regression!$O$24*dummy_variables!$E$33+multiple_regression!$O$25*dummy_variables!$F$33+multiple_regression!$O$26*dummy_variables!$G$33+multiple_regression!$O$27*dummy_variables!$H$33+multiple_regression!$O$28*dummy_variables!$I$33 -> 567895.74 | G33: =E33-F33 -> -56051.334
A34: =cleaned_data!$A$34 -> STR-1008 | B34: =cleaned_data!$B$34 -> 2025-02-01 | C34: =cleaned_data!$C$34 -> East | D34: =cleaned_data!$D$34 -> Residential | E34: =cleaned_data!$M$34 -> 537383.79 | F34: =multiple_regression!$O$18+multiple_regression!$O$19*cleaned_data!$F$34+multiple_regression!$O$20*cleaned_data!$E$34+multiple_regression!$O$21*cleaned_data!$I$34+multiple_regression!$O$22*cleaned_data!$H$34+multiple_regression!$O$23*dummy_variables!$D$34+multiple_regression!$O$24*dummy_variables!$E$34+multiple_regression!$O$25*dummy_variables!$F$34+multiple_regression!$O$26*dummy_variables!$G$34+multiple_regression!$O$27*dummy_variables!$H$34+multiple_regression!$O$28*dummy_variables!$I$34 -> 517388.62 | G34: =E34-F34 -> 19995.165
A35: =cleaned_data!$A$35 -> STR-1008 | B35: =cleaned_data!$B$35 -> 2025-03-01 | C35: =cleaned_data!$C$35 -> East | D35: =cleaned_data!$D$35 -> Residential | E35: =cleaned_data!$M$35 -> 500173.02 | F35: =multiple_regression!$O$18+multiple_regression!$O$19*cleaned_data!$F$35+multiple_regression!$O$20*cleaned_data!$E$35+multiple_regression!$O$21*cleaned_data!$I$35+multiple_regression!$O$22*cleaned_data!$H$35+multiple_regression!$O$23*dummy_variables!$D$35+multiple_regression!$O$24*dummy_variables!$E$35+multiple_regression!$O$25*dummy_variables!$F$35+multiple_regression!$O$26*dummy_variables!$G$35+multiple_regression!$O$27*dummy_variables!$H$35+multiple_regression!$O$28*dummy_variables!$I$35 -> 504237.41 | G35: =E35-F35 -> -4064.387
A36: =cleaned_data!$A$36 -> STR-1008 | B36: =cleaned_data!$B$36 -> 2025-04-01 | C36: =cleaned_data!$C$36 -> East | D36: =cleaned_data!$D$36 -> Residential | E36: =cleaned_data!$M$36 -> 427917.38 | F36: =multiple_regression!$O$18+multiple_regression!$O$19*cleaned_data!$F$36+multiple_regression!$O$20*cleaned_data!$E$36+multiple_regression!$O$21*cleaned_data!$I$36+multiple_regression!$O$22*cleaned_data!$H$36+multiple_regression!$O$23*dummy_variables!$D$36+multiple_regression!$O$24*dummy_variables!$E$36+multiple_regression!$O$25*dummy_variables!$F$36+multiple_regression!$O$26*dummy_variables!$G$36+multiple_regression!$O$27*dummy_variables!$H$36+multiple_regression!$O$28*dummy_variables!$I$36 -> 480318.57 | G36: =E36-F36 -> -52401.193
A37: =cleaned_data!$A$37 -> STR-1009 | B37: =cleaned_data!$B$37 -> 2025-01-01 | C37: =cleaned_data!$C$37 -> North | D37: =cleaned_data!$D$37 -> Residential | E37: =cleaned_data!$M$37 -> 641865.03 | F37: =multiple_regression!$O$18+multiple_regression!$O$19*cleaned_data!$F$37+multiple_regression!$O$20*cleaned_data!$E$37+multiple_regression!$O$21*cleaned_data!$I$37+multiple_regression!$O$22*cleaned_data!$H$37+multiple_regression!$O$23*dummy_variables!$D$37+multiple_regression!$O$24*dummy_variables!$E$37+multiple_regression!$O$25*dummy_variables!$F$37+multiple_regression!$O$26*dummy_variables!$G$37+multiple_regression!$O$27*dummy_variables!$H$37+multiple_regression!$O$28*dummy_variables!$I$37 -> 738721.32 | G37: =E37-F37 -> -96856.294
A38: =cleaned_data!$A$38 -> STR-1009 | B38: =cleaned_data!$B$38 -> 2025-02-01 | C38: =cleaned_data!$C$38 -> North | D38: =cleaned_data!$D$38 -> Residential | E38: =cleaned_data!$M$38 -> 799477.76 | F38: =multiple_regression!$O$18+multiple_regression!$O$19*cleaned_data!$F$38+multiple_regression!$O$20*cleaned_data!$E$38+multiple_regression!$O$21*cleaned_data!$I$38+multiple_regression!$O$22*cleaned_data!$H$38+multiple_regression!$O$23*dummy_variables!$D$38+multiple_regression!$O$24*dummy_variables!$E$38+multiple_regression!$O$25*dummy_variables!$F$38+multiple_regression!$O$26*dummy_variables!$G$38+multiple_regression!$O$27*dummy_variables!$H$38+multiple_regression!$O$28*dummy_variables!$I$38 -> 841917.75 | G38: =E38-F38 -> -42439.985
